Workbook
Name __bookmark_1: #REF!

Sheet W4Q3FY24
A1: MW | B1: MW | C1: TZ | D1: TZ | E1: FPT | F1: FPT | G1: CPS | H1: CPS | I1: Hoàng Hà | J1: Hoàng Hà | K1: SD | L1: SD | M1: Viettel | N1: Viettel
A2: iPhone 15 128Gb | B2: 19490000 | C2: iPhone 15 128Gb | D2: 19196000 | E2: iPhone 15 128Gb | F2: 19290000 | G2: iPhone 15 128 GB | H2: 19290000 | I2: iPhone 15 128Gb | J2: 18790000 | K2: iPhone 15 128Gb | L2: 18840000 | M2: iPhone 15 128 Gb | N2: 18990000
A3: iPhone 15 Plus 128Gb | B3: 22790000 | C3: iPhone 15 Plus 128Gb | D3: 22590000 | E3: iPhone 15 Plus 128Gb | F3: 21790000 | G3: iPhone 15 Plus 128 GB | H3: 22290000 | I3: iPhone 15 Plus 128Gb | J3: 21890000 | K3: iPhone 15 Plus 128Gb | L3: 21940000 | M3: iPhone 15 Plus 128 Gb | N3: 21990000
A4: iPhone 15 Pro 128Gb | B4: 25490000 | C4: iPhone 15 Pro 128Gb | D4: 24690000 | E4: iPhone 15 Pro 128Gb | F4: 24790000 | G4: iPhone 15 Pro 128 GB | H4: 24590000 | I4: iPhone 15 Pro 128Gb | J4: 23890000 | K4: iPhone 15 Pro 128Gb | L4: 24590000 | M4: iPhone 15 Pro 128 Gb | N4: 23990000
A5: iPhone 15 Pro Max 1256Gb | B5: 29990000 | C5: iPhone 15 Pro Max 256Gb | D5: 29190000 | E5: iPhone 15 Pro Max 256Gb | F5: 29290000 | G5: iPhone 15 Pro Max 256 GB | H5: 29090000 | I5: iPhone 15 Pro Max 128Gb | J5: 28690000 | K5: iPhone 15 Pro Max 256Gb | L5: 28790000 | M5: iPhone 15 Pro Max 256 Gb | N5: 28990000
A6: iPhone 14 128 Gb | B6: 16790000 | C6: iPhone 14 Pro Max 128GB | D6: 27190000 | E6: iPhone 14 Pro Max 128Gb | F6: OOS | G6: iPhone 14 128 GB | H6: 16990000 | I6: iPhone 14 Pro Max 128Gb | J6: N/A | K6: iPhone 14 Pro Max 128Gb | L6: 26550000 | M6: iPhone 14 128 Gb | N6: 16840000
A7: iPhone 14 Pro Max 128Gb | B7: 27390000 | C7: iPhone 14 Plus 128GB | D7: 19691000 | E7: iPhone 14 Pro 128Gb | F7: OOS | G7: iPhone 14 Plus 128GB | H7: 19390000 | I7: iPhone 14 Plus 128Gb | J7: 19690000 | K7: iPhone 14 Pro 128Gb | L7: 23890000 | M7: iPhone 14 Plus 128Gb | N7: 19990000
A8: iPhone 13 128GB | B8: 13990000 | C8: iPhone 14 128GB | D8: 16622000 | E8: iPhone 14 Plus 128Gb | F8: 19690000 | G8: iPhone 14 Pro 128GB | H8: OOS | I8: iPhone 14 128GB | J8: 16990000 | K8: iPhone 14 Plus 128Gb | L8: 19690000 | M8: iPhone 14 Pro Max 256Gb | N8: N/A
A9: iPhone 12 64GB | B9: 11990000 | C9: iPhone 13 128GB | D9: 13652000 | E9: iPhone 14 128Gb | F9: 16690000 | G9: iPhone 14 Pro Max 128GB | H9: 25590000 | I9: iPhone 13 128GB | J9: 13390000 | K9: iPhone 14 128 | L9: 16990000 | M9: iPhone 13 128GB | N9: 13190000
A10: iPhone 11 64GB | B10: 8990000 | C10: iPhone 12 64GB | D10: 11870000 | E10: iPhone 13 128GB | F10: 13690000 | G10: iPhone 13 128GB | H10: 13590000 | I10: iPhone 12 64GB | J10: 11990000 | K10: iPhone 13 128GB | L10: 13390000 | M10: iPhone 12 64GB | N10: 11990000
A11: MacBook Air M3 13' 256Gb | B11: 27990000 | C11: iPhone 11 64GB | D11: 8900000 | E11: iPhone 12 64GB | F11: 11890000 | G11: iPhone 12 64GB | H11: 11790000 | I11: iPhone 11 64GB | J11: 8790000 | K11: iPhone 12 64GB | L11: 12290000 | M11: iPhone 11 64GB | N11: 8790000
A12: MacBook Air M3 15' 256Gb | B12: 32690000 | C12: MacBook Air M3 13' 256Gb | D12: 27790000 | E12: iPhone 11 64GB | F12: 8940000 | G12: iPhone 11 64GB | H12: 8790000 | I12: MacBook Air M3 13' 256Gb | J12: 26890000 | K12: iPhone 11 64GB | L12: 8790000 | M12: iPad Pro M2 (Wi-fi 11” 128GB) | N12: 19990000
A13: MacBook Pro M3 14' | B13: 38690000 | C13: MacBook Air M3 15' 256Gb | D13: 32490000 | E13: MacBook Air M3 13' 256Gb | F13: 27890000 | G13: MacBook Air M3 13' 256Gb | H13: 27990000 | I13: MacBook Air M3 15' 256Gb | J13: 32990000 | K13: MacBook Air M3 13' 256Gb | L13: 27350000 | M13: iPad Air 5 (Wi-fi 64GB) | N13: 13990000
A14: MacBook Pro M3 Max 14' | B14: 79490000 | C14: MacBook Pro M3 14' | D14: 38790000 | E14: MacBook Air M3 15' 256Gb | F14: OOS | G14: MacBook Air M3 15' 256Gb | H14: 32490000 | I14: MacBook Pro M3 14' | J14: 37490000 | K14: MacBook Air M3 15' 256Gb | L14: 32450000 | M14: iPad Mini 6 (Wi-fi 64GB) | N14: 12,190,000
A15: MacBook Air M1 | B15: 18690000 | C15: MacBook Pro M3 Max 14' | D15: 79290000 | E15: MacBook Pro M3 14' | F15: OOS | G15: MacBook Pro M3 14' | H15: 37690000 | I15: MacBook Pro M3 Max 14' | J15: N/A | K15: MacBook Pro M3 14' | L15: 37490000 | M15: iPad 10th (Wi-fi 64GB) | N15: 9890000
A16: MacBook Air M2 | B16: 24990000 | C16: MacBook Air M1 | D16: 18305000 | E16: MacBook Pro M3 Max 14' | F16: 79190000 | G16: MacBook Pro M3 Max 14' | H16: 77990000 | I16: MacBook Air M1 | J16: 18290000 | K16: MacBook Pro M3 Max 14' | L16: 76990000 | M16: iPad 9th (Wi-fi 64GB) | N16: 7090000
A17: iPad Pro M2 (Wi-fi 11” 128GB) | B17: 20990000 | C17: MacBook Air M2 | D17: 24790000 | E17: MacBook Air M1 | F17: 18390000 | G17: MacBook Air M1 | H17: 18490000 | I17: MacBook Air M2 | J17: 24590000 | K17: MacBook Air M1 | L17: 18240000 | M17: Watch S8 (41mm GPS) | N17: 6990000
A18: iPad Air 5 (Wi-fi 64GB) | B18: 14390000 | C18: iPad Pro M2 (Wi-fi 11” 128GB) | D18: 20790000 | E18: MacBook Air M2 | F18: 24890000 | G18: MacBook Air M2 | H18: 24790000 | I18: MacBook Pro M2 | J18: 29790000 | K18: MacBook Air M2 | L18: 24590000 | M18: Watch S9 (41mm GPS) | N18: 8690000
A19: iPad Mini 6 (Wi-fi 64GB) | B19: 12390000 | C19: iPad Air 5 (Wi-fi 64GB) | D19: 14246000 | E19: MacBook Pro M2 | F19: OOS | G19: iPad Pro M1 (Wi-fi 11” 128GB) | H19: OOS | I19: iPad Pro M2 (Wi-fi 11” 128GB) | J19: 19990000 | K19: MacBook Pro M2 | L19: 29290000 | M19: Watch S9 (45mm GPS) | N19: 9990000
A20: iPad 10th (Wi-fi 64GB) | B20: 10290000 | C20: iPad Mini 6 (Wi-fi 64GB) | D20: 12266000 | E20: iPad Pro M2 (Wi-fi 11” 128GB) | F20: 20390000 | G20: iPad Pro M2 (Wi-fi 11” 128GB) | H20: 20790000 | I20: iPad Air 5 (Wi-fi 64GB) | J20: 14390000 | K20: iPad Air 5 (Wi-fi 64GB) | L20: 14390000 | M20: Watch SE 2022 (40mm GPS) | N20: 4990000
A21: iPad 9th (Wi-fi 64GB) | B21: 7090000 | C21: iPad Gen 10th (Wi-fi 64GB) | D21: 10187000 | E21: iPad Air 5 (Wi-fi 64GB) | F21: 14390000 | G21: iPad Air 5 (Wi-fi 64GB) | H21: 14390000 | I21: iPad Mini 6 (Wi-fi 64GB) | J21: 11190000 | K21: iPad Mini 6 (Wi-fi 64GB) | L21: 10940000 | M21: Watch SE 2023 (40mm GPS) | N21: 5690000
A22: Watch S9 (41mm LTE) | B22: 12890000 | C22: iPad 9th (Wi-fi 64GB) | D22: 7019000 | E22: iPad Mini 6 (Wi-fi 64GB) | F22: 11890000 | G22: iPad Mini 6 (Wi-fi 64GB) | H22: 11990000 | I22: iPad Gen 10th (Wi-fi 64GB) | J22: 9990000 | K22: iPad Gen 10th (Wi-fi 64GB) | L22: 9890000 | M22: Watch Ultra ( 49mm) | N22: 14790000
A23: Watch S9 (41mm GPS) | B23: 10190000 | C23: Watch S9 (41mm LTE) | D23: 12167000 | E23: iPad Gen 10th (Wi-fi 64GB) | F23: 9940000 | G23: iPad 9th (Wi-fi 64GB) | H23: 6990000 | I23: iPad 9th (Wi-fi 64GB) | J23: 6990000 | K23: iPad 9th (Wi-fi 64GB) | L23: 6990000 | M23: Watch Ultra 2 ( 49mm) | N23: 19690000
A24: Watch SE 3 (40mm GPS) | B24: 6190000 | C24: Watch S9 (41mm GPS) | D24: 9494000 | E24: iPad 9th (Wi-fi 64GB) | F24: 7140000 | G24: iPad 10th (Wi-fi 64GB) | H24: 9890000 | I24: Watch S9 (41mm LTE) | J24: 11890000 | K24: Watch 9 (41mm LTE) | L24: 11740000 | M24: AirPods Pro Gen 2 (Lightning) | N24: 5390000
A25: Watch SE 2 (40mm GPS) | B25: OOS | C25: Watch SE 3 (40mm GPS) | D25: 5930000 | E25: Watch S9 (41mm LTE) | F25: 12290000 | G25: Watch S9 (41mm LTE) | H25: 12290000 | I25: Watch S9 (41mm GPS) | J25: 8690000 | K25: Watch S9 (41mm GPS) | L25: 8940000 | M25: AirPods 3 (Lightning) | N25: 3790000
A26: Watch S8 (41mm GPS) | B26: N/A | C26: Watch Ultra 2 ( 49mm) | D26: 20790000 | E26: Watch S9 (41mm GPS) | F26: 9440000 | G26: Watch SE 3 (40mm GPS ) | H26: 5790000 | I26: Watch SE 3 (40mm GPS) | J26: N/A | K26: Watch SE 3 (40mm GPS) | L26: 5790000 | M26: AirPods 2 | N26: 2,790,000
A27: Watch Ultra 2 (49mm) | B27: 21990000 | C27: Watch S8 (41mm GPS) | D27: OOS | E27: Watch Ultra 2 ( 49mm) | F27: 20890000 | G27: Watch S9 (41mm GPS) | H27: 8990000 | I27: Watch Ultra 2 ( 49mm) | J27: 20890000 | K27: Watch Ultra 2 ( 49mm) | L27: 20890000
A28: Watch Ultra (49mm) | B28: OOS | C28: Watch Ultra ( 49mm) | D28: OOS | E28: Watch S3 (38mm GPS) | F28: OOS | G28: Watch Ultra 2 ( 49mm) | H28: 20990000 | I28: Watch SE2 (40mm GPS) | J28: 5290000 | K28: Watch SE2 (40mm GPS) | L28: 5890000
A29: AirPods Pro | B29: OOS | C29: AirPods Pro | D29: OOS | E29: Watch SE2 (40mm GPS) | F29: 5940000 | G29: Watch SE2 (40mm GPS) | H29: OOS | I29: Watch S8 (41mm GPS) | J29: 7490000 | K29: Watch S8 (41mm GPS) | L29: N/A
A30: AirPods Pro 2 | B30: 6190000 | C30: AirPods Pro 2 | D30: 5590000 | E30: Watch S8 (41mm GPS) | F30: OOS | G30: Watch S8 (41mm GPS) | H30: OOS | I30: Watch Ultra ( 49mm) | J30: 14990000 | K30: Watch Ultra ( 49mm) | L30: N/A
A31: AirPods 3 | B31: 4390000 | C31: AirPods 3 | D31: 3890000 | E31: Watch Ultra ( 49mm) | F31: 17390000 | G31: Watch Ultra ( 49mm) | H31: 15990000 | I31: AirPods Pro | J31: N/A | K31: AirPods Pro | L31: 4850000
A32: AirPods with charging case | B32: 2790000 | C32: AirPods with charging case | D32: 2650000 | E32: AirPods Pro | F32: OOS | G32: AirPods Pro | H32: 4450000 | I32: AirPods Pro 2 | J32: 5450000 | K32: AirPods Pro 2 | L32: 4990000
E33: AirPods Pro 2 | F33: 5500000 | G33: AirPods Pro 2 | H33: 5390000 | I33: AirPods 3 | J33: 3990000 | K33: AirPods 3 | L33: 3950000
E34: AirPods 3 | F34: 3890000 | G34: AirPods 3 | H34: 3890000 | I34: AirPods with charging case | J34: 2690000 | K34: AirPods with charging case | L34: 2750000
E35: AirPods 2 | F35: 2650000 | G35: AirPods with charging case | H35: 2650000

Sheet W5Q3FY24
B1: MW | C1: TZ | D1: FPT | E1: CPS | F1: HH | G1: SD | I1: VT
A2: iPhone 15 128Gb | B2: 19390000 | C2: 19390000 | D2: 19290000 | E2: 19290000 | F2: 18790000 | G2: 18850000 | I2: iPhone 15 128 Gb | J2: 18990000
A3: iPhone 15 Plus 128Gb | B3: 22790000 | C3: 22790000 | D3: 22490000 | E3: 22290000 | F3: 21890000 | G3: 21890000 | I3: iPhone 15 Plus 128 Gb | J3: 21990000
A4: iPhone 15 Pro 128Gb | B4: 24990000 | C4: 24990000 | D4: 24790000 | E4: 24590000 | F4: 23890000 | G4: 24590000 | I4: iPhone 15 Pro 128 Gb | J4: 23990000
A5: iPhone 15 Pro Max 128Gb | B5: 29590000 | C5: 29590000 | D5: 29390000 | E5: 29090000 | F5: 28690000 | G5: 28790000 | I5: iPhone 15 Pro Max 256 Gb | J5: 28990000
A6: iPhone 14 Plus 128Gb | B6: 19690000 | C6: 19690000 | D6: 19590000 | E6: 19390000 | F6: 19690000 | G6: 19690000 | I6: iPhone 14 128 Gb | J6: 16690000
A7: iPhone 14 128GB | B7: 16790000 | C7: 16790000 | D7: 16690000 | E7: 16990000 | F7: 16990000 | G7: 16990000 | I7: iPhone 14 Plus 128Gb | J7: 19990000
A8: iPhone 13 128GB | B8: 13890000 | C8: 13890000 | D8: 13690000 | E8: 13590000 | F8: 13390000 | G8: 13390000 | I8: iPhone 14 Pro Max 256Gb | J8: N/A
A9: iPhone 12 64GB | B9: 11990000 | C9: 11870000 | D9: 11890000 | E9: 11790000 | F9: 11990000 | G9: 11990000 | I9: iPhone 13 128GB | J9: 13190000
A10: iPhone 11 64GB | B10: 8990000 | C10: 8990000 | D10: 8940000 | E10: 8790000 | F10: 8790000 | G10: 8790000 | I10: iPhone 12 64GB | J10: 11990000
A11: iPad Pro M2 (Wi-fi 11” 128GB) | B11: 20990000 | C11: 20990000 | D11: 20390000 | E11: 20790000 | F11: 19990000 | G11: 20790000 | I11: iPhone 11 64GB | J11: 8590000
A12: iPad Air 5 (Wi-fi 64GB) | B12: 14590000 | C12: 14590000 | D12: 14290000 | E12: 14390000 | F12: 14390000 | G12: 13790000 | I12: iPad Pro M2 (Wi-fi 11” 128GB) | J12: 19790000
A13: iPad Mini 6 (Wi-fi 64GB) | B13: 12390000 | C13: 12390000 | D13: 11890000 | E13: 11990000 | F13: 11190000 | G13: 11190000 | I13: iPad Air 5 (Wi-fi 64GB) | J13: 13790000
A14: iPad Gen 10th (Wi-fi 64GB) | B14: 10290000 | C14: 10290000 | D14: 9940000 | E14: 6990000 | F14: 9990000 | G14: 9890000 | I14: iPad Mini 6 (Wi-fi 64GB) | J14: 12,190,000
A15: iPad 9th (Wi-fi 64GB) | B15: 7190000 | C15: 7190000 | D15: 7140000 | E15: 9890000 | F15: 6990000 | G15: 6990000 | I15: iPad 10th (Wi-fi 64GB) | J15: 9890000
A16: Watch S9 (41mm LTE) | B16: 12690000 | C16: 12290000 | D16: 12290000 | E16: 12290000 | F16: 11890000 | G16: 11740000 | I16: iPad 9th (Wi-fi 64GB) | J16: 7090000
A17: Watch S9 (41mm GPS) | B17: 9790000 | C17: 9790000 | D17: 9440000 | E17: 9190000 | F17: 8690000 | G17: 8940000 | I17: Watch S8 (41mm GPS) | J17: 6990000
A18: Watch Ultra 2 ( 49mm) | B18: 21990000 | C18: 20990000 | D18: 20890000 | E18: 20990000 | F18: 20890000 | G18: 20890000 | I18: Watch S9 (41mm GPS) | J18: 8690000
A19: Watch SE 2023 (40mm GPS) | B19: 5990000 | C19: 5990000 | D19: 5940000 | E19: 5790000 | F19: 5290000 | G19: 5290000 | I19: Watch S9 (45mm GPS) | J19: 9990000
A20: Watch Ultra ( 49mm) | B20: OOS | C20: OOS | D20: 17390000 | E20: 15990000 | F20: 14990000 | G20: 20890000 | I20: Watch SE 2022 (40mm GPS) | J20: 4990000
A21: AirPods Pro 2 | B21: 5790000 | C21: 5790000 | D21: 5640000 | E21: 5590000 | F21: 5450000 | G21: 4990000 | I21: Watch SE 2023 (40mm GPS) | J21: 5490000
A22: AirPods 3 | B22: 4090000 | C22: 4090000 | D22: 3890000 | E22: 3890000 | F22: 3990000 | G22: 3950000 | I22: Watch Ultra ( 49mm) | J22: 14790000
A23: AirPods with charging case | B23: 2790000 | C23: 2790000 | D23: 2650000 | E23: 2650000 | F23: 2690000 | G23: 2750000 | I23: Watch Ultra 2 ( 49mm) | J23: 19690000
A24: MacBook Air M3 13' 256Gb | B24: 27790000 | C24: 27790000 | D24: 27890000 | E24: 27990000 | F24: 26890000 | G24: 26840000 | I24: AirPods Pro Gen 2 (Lightning) | J24: 5390000
A25: MacBook Air M3 15' 256Gb | B25: 32190000 | C25: 32190000 | D25: 32690000 | E25: 31990000 | F25: 31990000 | G25: 31490000 | I25: AirPods 3 (Lightning) | J25: 3990000
A26: MacBook Pro M3 14' 256Gb | B26: 38690000 | C26: 38690000 | D26: OOS | E26: 37690000 | F26: 36990000 | G26: 37490000 | I26: AirPods 2 | J26: 2,790,000
A27: MacBook Air M1 13' 256Gb | B27: 18590000 | C27: 18590000 | D27: 18390000 | E27: 18490000 | F27: 18290000 | G27: 18240000
A28: MacBook Air M2 13' 256Gb | B28: 24990000 | C28: 24990000 | D28: OOS | E28: 24790000 | F28: 24590000 | G28: 24590000
A29: MacBook Pro M2 14' 512Gb | B29: OOS | C29: OOS | D29: OOS | E29: OOS | F29: N/A | G29: 29290000
A32: THÔNG TIN THỊ TRƯỜNG W5Q3FY24: 1. FPT SHOP: - Do thay đổi chiến lược kinh doanh nên Apple trở thành sản phẩm mục tiêu các shop FPT tập trung push sale để tăng doanh thu hoàn thành target doanh số. Chính vì vậy iPhone 15 Pro Max trở thành model được bán ra tốt nhất trong tuần mặc dù giá 29.990K cao hơn Viettel Store tới 1 triệu đồng. - iPhone 15 Plus trước kỳ nghỉ lễ được nhiều khách hàng tìm mua và gây Hot thì W5 vừa qua tại FPT Shop sụt giảm mạnh 20% do chủ yếu khách hàng tập trung mua chơi lễ trước. Mặt khác việc ép bán gói BH 2 năm cũng khiến nhiều khách hàng tầm trẻ, đối tượng chính mua iPhone 15 Plus né tránh và tìm mua chuỗi khác. - Non iPhone tuần qua bán ra xu hướng giảm chung từ iPad tới MacBook do nhu cầu mua sắm trong và sau lễ rất thấp. Ngoại trừ AW có sell-out tương đối ổn định đặc biệt model AW SE do khách hàng mua để trưng diện đi du lịch nghỉ dưỡng và tập luyện sức khỏe vào mùa hè. 2. MOBILE WORLD: - Doanh thu Apple tại hệ thống Topzone và MW tuần W5 vừa qua sập số do các shop đóng cửa nghỉ lễ 30/4 và 1/5 nên bị mất khách và traffic shop đã thấp lại càng kém hơn sau khi mở lại. - Cách tính doanh thu shop thay đổi từ tháng 5 tại hệ thống MW. Không tính doanh thu đơn Online cho shop mà chỉ tính 50% thưởng cho nhân viên trong ca làm trong khi đó mùa hè nắng nóng tỉ lệ đơn online gia tăng khiến nhân viên và SM chán nản. - Điểm sáng nhất của chính sách tháng 5 tại MW hiện nay là hỗ trợ trả góp 0% cho các sản phẩm Apple trên giá giảm CTKM giúp khách hàng được lợi về giá, kích cầu mua sắm. Bên cạnh đó MW ký kết chiến lược với các bên trả góp để tỉ lệ duyệt hồ sơ tốt hơn làm lợi thế cạnh tranh các chuỗi khác. Điều này rất có lợi cho bán Apple trong tháng 5. 3. VIETTEL STORE: - Tuần W5 vừa qua gần như các model bán tốt tại Viettel Store không thay đổi về giá nhưng để thúc đẩy tỉ lệ kích hoạt sim thì chuỗi có chiến lược mở kho số tặng kèm khách hàng mỗi chiếc iPhone bán ra tặng 01 sim khiến khách hàng rất happy. - Mặc dù giá tốt, hàng hóa đầy đủ thậm chí dư thừa các bản base iPhone tại hầu hết các shop nhưng không truyền thông nên Viettel Store vẫn không thể nâng được tỉ trọng sell-out tương xứng và tuần qua traffic giảm do nghỉ lễ khiến sell-out còn giảm sâu hơn rất đáng tiếc. - Non iPhone tại W4 Viettel bán ra khá tốt iPad gen 9th và AW S8 cho đối tượng khách thu nhập tầm trung, yêu cầu sản phẩm không quá cao cấp nhưng tới W5 do traffic giảm mạnh vào đầu tuần vì trùng kỳ nghỉ lễ và cuối tuần nắng nóng kéo dài khiến sell-out Non iPhone nhiều shop lớn cũng bán ra rất kém.

Sheet W6Q3FY24
B1: MW | C1: TZ | D1: FPT | E1: CPS | F1: HH | G1: SD | H1: VT
A2: iPhone 15 128Gb | B2: 19290000 | C2: 19290000 | D2: 19290000 | E2: 19290000 | F2: 18690000 | G2: 18800000 | H2: 18490000
A3: iPhone 15 Plus 128Gb | B3: 22290000 | C3: 22290000 | D3: 22190000 | E3: 22290000 | F3: 21890000 | G3: 21890000 | H3: 21990000
A4: iPhone 15 Pro 128Gb | B4: 23990000 | C4: 23990000 | D4: 24390000 | E4: 24590000 | F4: 23890000 | G4: 24590000 | H4: 23990000
A5: iPhone 15 Pro Max 256Gb | B5: 29590000 | C5: 29590000 | D5: 29390000 | E5: 29090000 | F5: 28690000 | G5: 28790000 | H5: 28990000
A6: iPhone 14 Plus 128Gb | B6: 19990000 | C6: 19390000 | D6: 19290000 | E6: 19390000 | F6: 18990000 | G6: 19690000 | H6: 19990000
A7: iPhone 14 128GB | B7: 16490000 | C7: 16490000 | D7: 16390000 | E7: 16990000 | F7: 16590000 | G7: 16990000 | H7: 16690000
A8: iPhone 13 128GB | B8: 13790000 | C8: 13790000 | D8: 13690000 | E8: 13590000 | F8: 13390000 | G8: 13390000 | H8: 13190000
A9: iPhone 12 64GB | B9: 11990000 | C9: 11990000 | D9: 11890000 | E9: 11790000 | F9: 11790000 | G9: 12290000 | H9: 11990000
A10: iPhone 11 64GB | B10: 8790000 | C10: 8790000 | D10: 8740000 | E10: 8790000 | F10: 8590000 | G10: 8790000 | H10: 8590000
A11: iPad Pro M2 (Wi-fi 11” 128GB) | B11: 20990000 | C11: 20990000 | D11: 20890000 | E11: 21190000 | F11: 19990000 | G11: 20790000 | H11: 19790000
A12: iPad Air 5 (Wi-fi 64GB) | B12: 14390000 | C12: 14390000 | D12: 14190000 | E12: 14290000 | F12: 13990000 | G12: 13790000 | H12: 13790000
A13: iPad Mini 6 (Wi-fi 64GB) | B13: 12390000 | C13: 12390000 | D13: 11890000 | E13: 11990000 | F13: 11690000 | G13: 11190000 | H13: 12,190,000
A14: iPad Gen 10th (Wi-fi 64GB) | B14: 10590000 | C14: 10590000 | D14: 9940000 | E14: 9790000 | F14: 9790000 | G14: 9890000 | H14: 9890000
A15: iPad 9th (Wi-fi 64GB) | B15: 7090000 | C15: 6990000 | D15: 7040000 | E15: 6990000 | F15: 6890000 | G15: 6990000 | H15: 7090000
A16: Watch S9 (41mm LTE) | B16: 12690000 | C16: 12290000 | D16: 12290000 | E16: 12290000 | F16: 11890000 | G16: 11540000 | H16: 11690000
A17: Watch S9 (41mm GPS) | B17: 9390000 | C17: 9390000 | D17: 9440000 | E17: 8990000 | F17: 8690000 | G17: 8740000 | H17: 8890000
A18: Watch Ultra 2 ( 49mm) | B18: 20990000 | C18: 20990000 | D18: 20890000 | E18: 20990000 | F18: 20890000 | G18: 20890000 | H18: 19690000
A19: Watch SE 2023 (40mm GPS) | B19: 5890000 | C19: 5990000 | D19: 5940000 | E19: 5690000 | F19: 5690000 | G19: 5790000 | H19: 5690000
A20: Watch Ultra ( 49mm) | B20: OOS | C20: OOS | D20: 17390000 | E20: 15990000 | F20: 14990000 | G20: OOS | H20: 14790000
A21: AirPods Pro 2 | B21: 5390000 | C21: 5650000 | D21: 5640000 | E21: 5590000 | F21: 5450000 | G21: 4990000 | H21: 5390000
A22: AirPods 3 | B22: 4190000 | C22: 4199000 | D22: 4190000 | E22: 3990000 | F22: 3850000 | G22: 3950000 | H22: 3990000
A23: AirPods with charging case | B23: 2700000 | C23: 2700000 | D23: 2690000 | E23: 2690000 | F23: 2590000 | G23: 2750000 | H23: 2,790,000
A24: MacBook Air M3 13' 256Gb | B24: 27290000 | C24: 27290000 | D24: 27890000 | E24: 27590000 | F24: 26890000 | G24: 26840000
A25: MacBook Air M3 15' 256Gb | B25: 31690000 | C25: 31690000 | D25: 31390000 | E25: 31990000 | F25: 31990000 | G25: 31490000
A26: MacBook Pro M3 14' 256Gb | B26: OOS | C26: 38490000 | D26: OOS | E26: 38290000 | F26: 36990000 | G26: 37490000
A27: MacBook Air M1 13' 256Gb | B27: 18190000 | C27: 18190000 | D27: 18090000 | E27: 18390000 | F27: 18190000 | G27: 18240000
A28: MacBook Air M2 13' 256Gb | B28: 24590000 | C28: 24590000 | D28: OOS | E28: 24590000 | F28: 24590000 | G28: 24590000
A29: MacBook Pro M2 14' 256Gb | B29: OOS | C29: OOS | D29: OOS | E29: N/A | F29: N/A | G29: OOS

Sheet W7Q3FY24
B1: MW | C1: TZ | D1: FPT | E1: Viettel | F1: CPS | G1: Hoang Ha | H1: Shopdunk | I1: Shopee
A2: iPhone 15 128GB | B2: 19190000 | C2: 19190000 | D2: 19090000 | E2: 18490000 | F2: 18690000 | G2: 18690000 | H2: 18740000 | I2: 18415000
A3: iPhone 15 Plus 128GB | B3: 22190000 | C3: 22190000 | D3: 22090000 | E3: 21990000 | F3: 21790000 | G3: 21890000 | H3: 21890000 | I3: 21517000
A4: iPhone 15 Pro 128GB | B4: 24690000 | C4: 24690000 | D4: 24590000 | E4: 23990000 | F4: 24190000 | G4: 23890000 | H4: 24590000 | I4: 24337000
A5: iPhone 15 Pro Max 256GB | B5: 29590000 | C5: 29590000 | D5: 29390000 | E5: 28990000 | F5: 28690000 | G5: 28690000 | H5: 28590000 | I5: 29037000
A6: iPhone 14 Plus 128GB | B6: 19390000 | C6: 19390000 | D6: 19290000 | E6: 19290000 | F6: 19190000 | G6: 18990000 | H6: 19690000 | I6: 23021000
A7: iPhone 14 128GB | B7: 16490000 | C7: 16490000 | D7: 16390000 | E7: 16390000 | F7: 16390000 | G7: 16590000 | H7: 16990000 | I7: 16065000
A8: iPhone 13 128GB | B8: 13690000 | C8: 13690000 | D8: 13590000 | E8: 13190000 | F8: 13390000 | G8: 13390000 | H8: 13390000 | I8: 12775000
A9: iPhone 12 64GB | B9: 11990000 | C9: 11990000 | D9: 11890000 | E9: 11990000 | F9: OOS | G9: 11790000 | H9: 12290000 | I9: OOS
A10: iPhone 11 64GB | B10: 8690000 | C10: 8690000 | D10: 8640000 | E10: 8590000 | F10: 8550000 | G10: 8590000 | H10: 8690000 | I10: OOS
A11: iPad Pro 11" M2 128GB Wifi | B11: 21190000 | C11: 21190000 | D11: 20890000 | E11: 19790000 | F11: OOS | G11: 19990000 | H11: 20790000 | I11: 21799000
A12: iPad Air 5 M1 64GB Wifi | B12: 14090000 | C12: 14090000 | D12: 13990000 | E12: 14490000 | F12: 14090000 | G12: 13990000 | H12: 13790000 | I12: 13991000
A13: iPad Mini 6 64GB Wifi | B13: 12390000 | C13: 12390000 | D13: 11890000 | E13: 12,190,000 | F13: 11790000 | G13: 11690000 | H13: 11190000 | I13: 11271000
A14: iPad Gen 10th 64GB Wifi | B14: 10590000 | C14: 10590000 | D14: 9940000 | E14: 10790000 | F14: 9590000 | G14: 9790000 | H14: 9890000 | I14: 9673000
A15: iPad Gen 9th 64GB Wifi | B15: 7090000 | C15: 7090000 | D15: 7040000 | E15: 6990000 | F15: 6890000 | G15: 6890000 | H15: 6890000 | I15: 6853000
A16: AW SE 2023 (40mm GPS) | B16: 6090000 | C16: 5990000 | D16: 5740000 | E16: 5690000 | F16: 5590000 | G16: 5690000 | H16: 5790000 | I16: 5631000
A17: AW SE 2023 (40mm LTE) | B17: 7390000 | C17: 7390000 | D17: 7240000 | E17: 7190000 | F17: 7190000 | G17: 7190000 | H17: 7390000 | I17: OOS
A18: AW SE 2023 (44mm GPS) | B18: 6990000 | C18: 6890000 | D18: 6240000 | E18: 6590000 | F18: 6490000 | G18: 6590000 | H18: 6590000 | I18: OOS
A19: AW SE 2023 (44mm LTE) | B19: 8390000 | C19: 8190000 | D19: 7940000 | E19: 7990000 | F19: 7990000 | G19: 7890000 | H19: 7890000 | I19: OOS
A20: AW S9 (41mm GPS) | B20: 9390000 | C20: 9390000 | D20: 9340000 | E20: 8890000 | F20: 8890000 | G20: 8690000 | H20: 8740000 | I20: 9079000
A21: AW S9 (41mm CEL) | B21: 12590000 | C21: 12590000 | D21: 12290000 | E21: 11690000 | F21: 12090000 | G21: 11890000 | H21: 11540000 | I21: OOS
A22: AW S9 (45mm GPS) | B22: 10790000 | C22: 10790000 | D22: 10490000 | E22: 10290000 | F22: 10490000 | G22: 9990000 | H22: 9940000 | I22: OOS
A23: AW S9 (45mm CEL) | B23: 13690000 | C23: 13690000 | D23: 13390000 | E23: 12190000 | F23: 13290000 | G23: 12890000 | H23: 12640000 | I23: OOS
A24: AW Ultra 2 (49mm) | B24: 20990000 | C24: 21190000 | D24: 20890000 | E24: 19690000 | F24: 20790000 | G24: 20890000 | H24: 20890000 | I24: OOS
A25: AirPods Pro 2 - 2023 (C-Type) | B25: 5390000 | C25: 5650000 | D25: 5640000 | E25: 5490000 | F25: 5450000 | G25: 5450000 | H25: 5450000 | I25: OOS
A26: AirPods 3 with charging case | B26: 4090000 | C26: 4090000 | D26: 4190000 | E26: 3990000 | F26: 3990000 | G26: 3850000 | H26: 3950000 | I26: OOS
A27: AirPods 2 with charging case | B27: 2700000 | C27: 2700000 | D27: 2690000 | E27: 2,790,000 | F27: 2690000 | G27: 2590000 | H27: 2750000 | I27: 2567000
A28: MacBook Air 13" M1 8/256Gb | B28: 18190000 | C28: 18190000 | D28: 18090000 | F28: 17990000 | G28: 18190000 | H28: 18140000 | I28: 17663000
A29: MacBook Air 13" M2 8/256GB | B29: 24190000 | C29: 24190000 | D29: OOS | F29: 24090000 | G29: 24590000 | H29: 23790000 | I29: 24807000
A30: MacBook Air 13" M3 8/256GB | B30: 27290000 | C30: 27290000 | D30: 27190000 | F30: 26290000 | G30: 26890000 | H30: 26840000 | I30: OOS
A31: MacBook Air 15" M3 8/256GB | B31: 31490000 | C31: 31490000 | D31: 31190000 | F31: 30790000 | G31: 31990000 | H31: 31490000 | I31: OOS
A32: MacBook Pro 14" M3 8/512GB | B32: N/A | C32: 38490000 | D32: 38190000 | F32: 37290000 | G32: 36990000 | H32: 37490000 | I32: OOS

Sheet W8Q3FY24
B1: MW | C1: TZ | D1: FPT | E1: Viettel | F1: CPS | G1: Hoang Ha | H1: Shopdunk | I1: Shopee
A2: iPhone 15 128GB | B2: 18990000 | C2: 18990000 | D2: 18890000 | E2: 18490000 | F2: 18590000 | G2: 18690000 | H2: 18740000 | I2: 18023000
A3: iPhone 15 Plus 128GB | B3: 22190000 | C3: 22190000 | D3: 22090000 | E3: 21990000 | F3: 21590000 | G3: 21690000 | H3: 21740000 | I3: 20783000
A4: iPhone 15 Pro 128GB | B4: 24590000 | C4: 24590000 | D4: 24490000 | E4: 23990000 | F4: 24190000 | G4: 23890000 | H4: 23740000 | I4: 23819000
A5: iPhone 15 Pro Max 256GB | B5: 29290000 | C5: 29290000 | D5: 29390000 | E5: 28990000 | F5: 28590000 | G5: 28590000 | H5: 28690000 | I5: 28443000
A6: iPhone 14 Plus 128GB | B6: 19390000 | C6: 19390000 | D6: 19290000 | E6: 19290000 | F6: 19190000 | G6: 18990000 | H6: 19690000 | I6: 23021000
A7: iPhone 14 128GB | B7: 16490000 | C7: 16490000 | D7: 16390000 | E7: 16390000 | F7: 16390000 | G7: 16290000 | H7: 16990000 | I7: 15539000
A8: iPhone 13 128GB | B8: 13690000 | C8: 13690000 | D8: 13590000 | E8: 13190000 | F8: 13390000 | G8: 13390000 | H8: 13390000 | I8: 12779000
A9: iPhone 12 64GB | B9: 11590000 | C9: 11590000 | D9: 11490000 | E9: 11990000 | F9: OOS | G9: 11790000 | H9: 12290000 | I9: OOS
A10: iPhone 11 64GB | B10: 8690000 | C10: 8690000 | D10: 8640000 | E10: 8590000 | F10: 8550000 | G10: 8490000 | H10: 8490000 | I10: OOS
A11: iPad Pro 11" M2 128GB Wifi | B11: 21790000 | C11: 21190000 | D11: 20890000 | E11: 19790000 | F11: OOS | G11: 19990000 | H11: 20790000 | I11: OOS
A12: iPad Air 5 M1 64GB Wifi | B12: 13890000 | C12: 13890000 | D12: 13990000 | E12: 14490000 | F12: 14090000 | G12: 13990000 | H12: 13790000 | I12: 13607000
A13: iPad Mini 6 64GB Wifi | B13: 12890000 | C13: 12390000 | D13: 12290000 | E13: 12,190,000 | F13: 11990000 | G13: 11690000 | H13: 11190000 | I13: 10939000
A14: iPad Gen 10th 64GB Wifi | B14: 10590000 | C14: 10590000 | D14: 9940000 | E14: 9690000 | F14: 9590000 | G14: 9790000 | H14: 9890000 | I14: 9191000
A15: iPad Gen 9th 64GB Wifi | B15: 7090000 | C15: 7090000 | D15: 7040000 | E15: 6990000 | F15: 6890000 | G15: 6690000 | H15: 6890000 | I15: 6707000
A16: AW SE 2023 (40mm GPS) | B16: 5990000 | C16: 5990000 | D16: 5940000 | E16: 5690000 | F16: 5590000 | G16: 5690000 | H16: 5790000 | I16: 5511000
A17: AW SE 2023 (40mm LTE) | B17: 7390000 | C17: 7390000 | D17: 7240000 | E17: 7190000 | F17: 7190000 | G17: 7190000 | H17: 7390000 | I17: OOS
A18: AW SE 2023 (44mm GPS) | B18: 6990000 | C18: 6990000 | D18: 6740000 | E18: 6590000 | F18: 6490000 | G18: 6590000 | H18: 6590000 | I18: OOS
A19: AW SE 2023 (44mm LTE) | B19: 7990000 | C19: 8190000 | D19: 7940000 | E19: 7990000 | F19: 7990000 | G19: 7890000 | H19: 7890000 | I19: OOS
A20: AW S9 (41mm GPS) | B20: 9390000 | C20: 9390000 | D20: 9340000 | E20: 8690000 | F20: 8490000 | G20: 8690000 | H20: 8740000 | I20: 9099000
A21: AW S9 (41mm CEL) | B21: 12390000 | C21: 12390000 | D21: 12290000 | E21: 11690000 | F21: 11790000 | G21: 11890000 | H21: 11540000 | I21: 12690000
A22: AW S9 (45mm GPS) | B22: 10790000 | C22: 10790000 | D22: 10490000 | E22: 9890000 | F22: 10190000 | G22: 9990000 | H22: 9940000 | I22: OOS
A23: AW S9 (45mm CEL) | B23: 13690000 | C23: 13690000 | D23: 13390000 | E23: 12190000 | F23: 12990000 | G23: 12890000 | H23: 12640000 | I23: OOS
A24: AW Ultra 2 (49mm) | B24: 20990000 | C24: 21190000 | D24: 20890000 | E24: 19690000 | F24: 19990000 | G24: 20890000 | H24: 20890000 | I24: OOS
A25: AirPods Pro 2 - 2023 (C-Type) | B25: 5390000 | C25: 5590000 | D25: 5540000 | E25: 5490000 | F25: 5450000 | G25: 5450000 | H25: 5450000 | I25: OOS
A26: AirPods 3 with charging case | B26: 3990000 | C26: 3990000 | D26: 3990000 | E26: 3990000 | F26: 3990000 | G26: 3790000 | H26: 3950000 | I26: 3763000
A27: AirPods 2 with charging case | B27: 2690000 | C27: 2690000 | D27: 2690000 | E27: 2,690,000 | F27: 2690000 | G27: 2590000 | H27: 2750000 | I27: 2623000
A28: MacBook Air 13" M1 8/256Gb | B28: 18490000 | C28: 18490000 | D28: 18390000 | F28: 18290000 | G28: 17990000 | H28: 17940000 | I28: 17287000
A29: MacBook Air 13" M2 8/256GB | B29: 23990000 | C29: 24090000 | D29: 23990000 | F29: 23790000 | G29: 23990000 | H29: 23790000 | I29: 23435000
A30: MacBook Air 13" M3 8/256GB | B30: 27290000 | C30: 27890000 | D30: 27190000 | F30: 26190000 | G30: 26890000 | H30: 26840000 | I30: OOS
A31: MacBook Air 15" M3 8/256GB | B31: 31490000 | C31: 31490000 | D31: 31190000 | F31: 30790000 | G31: 31990000 | H31: 31490000 | I31: OOS
A32: MacBook Pro 14" M3 8/512GB | B32: N/A | C32: 38790000 | D32: 38190000 | F32: 37290000 | G32: 36990000 | H32: 37490000 | I32: OOS

Sheet W9Q3FY24
B1: MW | C1: TZ | D1: FPT | E1: Viettel | F1: CPS | G1: Hoang Ha | H1: Shopdunk | I1: Shopee
A2: iPhone 15 128GB | B2: 18800000 | C2: 18990000 | D2: 18990000 | E2: 18490000 | F2: 18590000 | G2: 18690000 | H2: 18740000 | I2: 17890000
A3: iPhone 15 Plus 128GB | B3: 21990000 | C3: 22190000 | D3: 22090000 | E3: 21990000 | F3: 21590000 | G3: 21690000 | H3: 21740000 | I3: 21059000
A4: iPhone 15 Pro 128GB | B4: 25490000 | C4: 25690000 | D4: 24690000 | E4: 23990000 | F4: 24390000 | G4: 23890000 | H4: 23740000 | I4: 23819000
A5: iPhone 15 Pro Max 256GB | B5: 29390000 | C5: 29590000 | D5: 29390000 | E5: 28990000 | F5: 28590000 | G5: 28590000 | H5: 28690000 | I5: 28419000
A6: iPhone 14 Plus 128GB | B6: 19196000 | C6: 19390000 | D6: 19290000 | E6: 19290000 | F6: 19190000 | G6: 18990000 | H6: 19690000 | I6: OOS
A7: iPhone 14 128GB | B7: 16226000 | C7: 16390000 | D7: 16290000 | E7: 16390000 | F7: 16390000 | G7: 16290000 | H7: 16990000 | I7: 15723000
A8: iPhone 13 128GB | B8: 13553000 | C8: 13690000 | D8: 13590000 | E8: 13190000 | F8: 13190000 | G8: 13190000 | H8: 13190000 | I8: 12779000
A9: iPhone 12 64GB | B9: 11474000 | C9: 11590000 | D9: 11490000 | E9: 11990000 | F9: OOS | G9: 11790000 | H9: 12290000 | I9: OOS
A10: iPhone 11 64GB | B10: 8603000 | C10: 8690000 | D10: 8640000 | E10: 8590000 | F10: 8550000 | G10: 8490000 | H10: 8490000 | I10: OOS
A11: iPad Pro 11" M2 128GB Wifi | B11: OOS | C11: 21990000 | D11: 20890000 | E11: 19790000 | F11: OOS | G11: 19990000 | H11: 20790000 | I11: OOS
A12: iPad Air 5 M1 64GB Wifi | B12: 13949000 | C12: 14090000 | D12: 13790000 | E12: 14490000 | F12: 14490000 | G12: 13990000 | H12: 13790000 | I12: 13699000
A13: iPad Mini 6 64GB Wifi | B13: 12266000 | C13: 12390000 | D13: 12290000 | E13: 12,190,000 | F13: 11990000 | G13: 11690000 | H13: 11190000 | I13: 11031000
A14: iPad Gen 10th 64GB Wifi | B14: 10484000 | C14: 10590000 | D14: 9940000 | E14: 9490000 | F14: 9590000 | G14: 9790000 | H14: 9690000 | I14: 9283000
A15: iPad Gen 9th 64GB Wifi | B15: 7118000 | C15: 7190000 | D15: 7040000 | E15: 6790000 | F15: 6790000 | G15: 6890000 | H15: 6890000 | I15: 6707000
A16: AW SE 2023 (40mm GPS) | B16: 5930000 | C16: 5790000 | D16: 5740000 | E16: 5690000 | F16: 5590000 | G16: 5690000 | H16: 5790000 | I16: 5503000
A17: AW SE 2023 (40mm LTE) | B17: 7217000 | C17: 7290000 | D17: 7240000 | E17: 7190000 | F17: 7190000 | G17: 7190000 | H17: 7390000 | I17: OOS
A18: AW SE 2023 (44mm GPS) | B18: 6821000 | C18: 6890000 | D18: 6740000 | E18: 6590000 | F18: 6490000 | G18: 6590000 | H18: 6590000 | I18: 6891000
A19: AW SE 2023 (44mm LTE) | B19: 8009000 | C19: 7890000 | D19: 7940000 | E19: 7990000 | F19: 7990000 | G19: 7890000 | H19: 7890000 | I19: OOS
A20: AW S9 (41mm GPS) | B20: 9593000 | C20: 9190000 | D20: 9040000 | E20: 8690000 | F20: 8490000 | G20: 8690000 | H20: 8640000 | I20: 9099000
A21: AW S9 (41mm CEL) | B21: 11969000 | C21: 12790000 | D21: 11990000 | E21: 11690000 | F21: 11790000 | G21: 11890000 | H21: 11540000 | I21: OOS
A22: AW S9 (45mm GPS) | B22: 10583000 | C22: 10690000 | D22: 10490000 | E22: 9890000 | F22: 10190000 | G22: 9990000 | H22: 9940000 | I22: OOS
A23: AW S9 (45mm CEL) | B23: 13690000 | C23: 13690000 | D23: 13390000 | E23: 12190000 | F23: 12990000 | G23: 12890000 | H23: 12640000 | I23: OOS
A24: AW Ultra 2 (49mm) | B24: 20590000 | C24: 21090000 | D24: 20890000 | E24: 19690000 | F24: 19990000 | G24: 20890000 | H24: 20890000 | I24: OOS
A25: AirPods Pro 2 - 2023 (C-Type) | B25: 5390000 | C25: 5590000 | D25: 5540000 | E25: 5490000 | F25: 5450000 | G25: 5450000 | H25: 5450000 | I25: OOS
A26: AirPods 3 with charging case | B26: 3890000 | C26: 3890000 | D26: 3990000 | E26: 3990000 | F26: 3990000 | G26: 3790000 | H26: 3950000 | I26: OOS
A27: AirPods 2 with charging case | B27: 2690000 | C27: 2690000 | D27: 2690000 | E27: 2,690,000 | F27: 2690000 | G27: 2590000 | H27: 2690000 | I27: 2790000
A28: MacBook Air 13" M1 8/256Gb | B28: 18490000 | C28: 18490000 | D28: 18390000 | F28: 18290000 | G28: 18190000 | H28: 17940000 | I28: 17287000
A29: MacBook Air 13" M2 8/256GB | B29: 23790000 | C29: 23990000 | D29: 23890000 | F29: 23690000 | G29: 23990000 | H29: 23490000 | I29: 23635000
A30: MacBook Air 13" M3 8/256GB | B30: 27090000 | C30: 27290000 | D30: 27190000 | F30: 26190000 | G30: 26890000 | H30: 26840000 | I30: OOS
A31: MacBook Air 15" M3 8/256GB | B31: 31290000 | C31: 31490000 | D31: 31190000 | F31: 30790000 | G31: 31990000 | H31: 31490000 | I31: OOS
A32: MacBook Pro 14" M3 8/512GB | B32: N/A | C32: 38490000 | D32: 38190000 | F32: 37290000 | G32: 36990000 | H32: 37490000 | I32: OOS

Sheet W10Q3FY24
B1: MW | C1: TZ | D1: FPT | E1: Viettel | F1: CPS | G1: Hoang Ha | H1: Shopdunk | I1: Shopee
A2: iPhone 15 128GB | B2: 18998000 | C2: 19190000 | D2: 19090000 | E2: 18990000 | F2: 18790000 | G2: 18690000 | H2: 18740000 | I2: 18023000
A3: iPhone 15 Plus 128GB | B3: 21790000 | C3: 21990000 | D3: 21990000 | E3: 21990000 | F3: 21490000 | G3: 21790000 | H3: 21740000 | I3: 20783000
A4: iPhone 15 Pro 128GB | B4: 25990000 | C4: 26190000 | D4: 25590000 | E4: 24490000 | F4: 24890000 | G4: 24090000 | H4: 24290000 | I4: 23490000
A5: iPhone 15 Pro Max 256GB | B5: 29590000 | C5: 29790000 | D5: 29390000 | E5: 29990000 | F5: 28890000 | G5: 28690000 | H5: 28890000 | I5: 28490000
A6: iPhone 14 Plus 128GB | B6: 19196000 | C6: 19390000 | D6: 19290000 | E6: 19490000 | F6: 19190000 | G6: 18990000 | H6: 18990000 | I6: 23031000
A7: iPhone 14 128GB | B7: 17414000 | C7: 17590000 | D7: 17090000 | E7: 16390000 | F7: 16590000 | G7: 16290000 | H7: 16290000 | I7: 15723000
A8: iPhone 13 128GB | B8: 13454000 | C8: 13590000 | D8: 13690000 | E8: 13490000 | F8: 13190000 | G8: 13190000 | H8: 13390000 | I8: 12687000
A9: iPhone 12 64GB | B9: 11474000 | C9: 11590000 | D9: 11490000 | E9: 11490000 | F9: OOS | G9: 11790000 | H9: 12290000 | I9: OOS
A10: iPhone 11 64GB | B10: 8603000 | C10: 8680000 | D10: 8640000 | E10: 8790000 | F10: 8550000 | G10: 8590000 | H10: 8490000 | I10: OOS
A11: iPad Pro 11" M2 128GB Wifi | B11: OOS | C11: OOS | D11: 20890000 | E11: N/A | F11: OOS | G11: 19990000 | H11: 20790000 | I11: OOS
A12: iPad Air 5 M1 64GB Wifi | B12: 13949000 | C12: 14090000 | D12: 13990000 | E12: 14290000 | F12: 14490000 | G12: 13990000 | H12: 14290000 | I12: 13515000
A13: iPad Mini 6 64GB Wifi | B13: 12266000 | C13: 12390000 | D13: 12690000 | E13: 12,190,000 | F13: 12190000 | G13: 11690000 | H13: 12190000 | I13: 11031000
A14: iPad Gen 10th 64GB Wifi | B14: 10187000 | C14: 10290000 | D14: 9940000 | E14: 9690000 | F14: 9590000 | G14: 9490000 | H14: 9690000 | I14: 9391000
A15: iPad Gen 9th 64GB Wifi | B15: 7118000 | C15: 7190000 | D15: 7140000 | E15: 6990000 | F15: 6790000 | G15: 6890000 | H15: 6890000 | I15: 6561000
A16: AW SE 2023 (40mm GPS) | B16: 5930000 | C16: 5790000 | D16: 5740000 | E16: 5690000 | F16: 5690000 | G16: 5690000 | H16: 5790000 | I16: 5083000
A17: AW SE 2023 (40mm LTE) | B17: 7217000 | C17: 7290000 | D17: 7240000 | E17: 7190000 | F17: 7190000 | G17: 7190000 | H17: 7390000 | I17: OOS
A18: AW SE 2023 (44mm GPS) | B18: 6821000 | C18: 6890000 | D18: 6740000 | E18: 6590000 | F18: 6490000 | G18: 6590000 | H18: 6590000 | I18: 6577000
A19: AW SE 2023 (44mm LTE) | B19: 8009000 | C19: 8090000 | D19: 7940000 | E19: 7990000 | F19: 7990000 | G19: 7890000 | H19: 7890000 | I19: OOS
A20: AW S9 (41mm GPS) | B20: 9593000 | C20: 9190000 | D20: 9040000 | E20: 8690000 | F20: 8490000 | G20: 8690000 | H20: 8890000 | I20: 9209000
A21: AW S9 (41mm CEL) | B21: 11969000 | C21: 12090000 | D21: 11990000 | E21: 11690000 | F21: 11790000 | G21: 11890000 | H21: 11540000 | I21: OOS
A22: AW S9 (45mm GPS) | B22: 10583000 | C22: 10490000 | D22: 10490000 | E22: 9890000 | F22: 10190000 | G22: 9990000 | H22: 9940000 | I22: OOS
A23: AW S9 (45mm CEL) | B23: 13690000 | C23: 13690000 | D23: 13390000 | E23: 12190000 | F23: 12990000 | G23: 12890000 | H23: 12640000 | I23: OOS
A24: AW Ultra 2 (49mm) | B24: 20790000 | C24: 20990000 | D24: 20890000 | E24: 19990000 | F24: 19990000 | G24: 20890000 | H24: 20890000 | I24: OOS
A25: AirPods Pro 2 - 2023 (C-Type) | B25: 5390000 | C25: 5590000 | D25: 5540000 | E25: 5290000 | F25: 5450000 | G25: 5450000 | H25: 5450000 | I25: OOS
A26: AirPods 3 with charging case | B26: 4090000 | C26: 4090000 | D26: 4090000 | E26: 3790000 | F26: 3850000 | G26: 3790000 | H26: 3950000 | I26: OOS
A27: AirPods 2 with charging case | B27: 2690000 | C27: 2690000 | D27: 2690000 | E27: 2,690,000 | F27: 2690000 | G27: 2590000 | H27: 2690000 | I27: 2511000
A28: MacBook Air 13" M1 8/256Gb | B28: 18800000 | C28: 18990000 | D28: 18690000 | F28: 18490000 | G28: 18190000 | H28: 17940000 | I28: 17287000
A29: MacBook Air 13" M2 8/256GB | B29: 2379000 | C29: 23890000 | D29: 23990000 | F29: 23890000 | G29: 23990000 | H29: 23990000 | I29: 23490000
A30: MacBook Air 13" M3 8/256GB | B30: 26918000 | C30: 27190000 | D30: 27190000 | F30: 26390000 | G30: 26890000 | H30: 26840000 | I30: OOS
A31: MacBook Air 15" M3 8/256GB | B31: 31290000 | C31: 31490000 | D31: 31190000 | F31: 30790000 | G31: 31990000 | H31: 31490000 | I31: OOS
A32: MacBook Pro 14" M3 8/512GB | B32: N/A | C32: 38490000 | D32: 38190000 | F32: 37490000 | G32: 36990000 | H32: 37490000 | I32: OOS

Sheet W11Q3FY24
B1: MW | C1: TZ | D1: FPT | E1: Viettel | F1: CPS | G1: Hoang Ha | H1: Shopdunk | I1: Shopee
A2: iPhone 15 128GB | B2: 19493000 | C2: 19690000 | D2: 19590000 | E2: 18990000 | F2: 21790000 | G2: 18690000 | H2: 18740000 | I2: 18697000
A3: iPhone 15 Plus 128GB | B3: 22190000 | C3: 22390000 | D3: 22290000 | E3: 21990000 | F3: 21790000 | G3: 21790000 | H3: 21740000 | I3: 21329000
A4: iPhone 15 Pro 128GB | B4: 25690000 | C4: 25890000 | D4: 25590000 | E4: 24490000 | F4: 24690000 | G4: 24090000 | H4: 24290000 | I4: 24337000
A5: iPhone 15 Pro Max 256GB | B5: 29790000 | C5: 29990000 | D5: 29690000 | E5: 29990000 | F5: 28990000 | G5: 28890000 | H5: 28890000 | I5: 28943000
A6: iPhone 14 Plus 128GB | B6: 19592000 | C6: 19590000 | D6: 19490000 | E6: 19490000 | F6: 19190000 | G6: 18990000 | H6: 18990000 | I6: OOS
A7: iPhone 14 128GB | B7: 17513000 | C7: 17690000 | D7: 17590000 | E7: 16390000 | F7: 16890000 | G7: 16290000 | H7: 16290000 | I7: OOS
A8: iPhone 13 128GB | B8: 13949000 | C8: 14090000 | D8: 13990000 | E8: 13490000 | F8: 13390000 | G8: 13190000 | H8: 13390000 | I8: 13057000
A9: iPhone 12 64GB | B9: 11870000 | C9: 11990000 | D9: 11990000 | E9: 11490000 | F9: OOS | G9: 11790000 | H9: 12290000 | I9: OOS
A10: iPhone 11 64GB | B10: 8504000 | C10: 8590000 | D10: 8590000 | E10: 8790000 | F10: 8490000 | G10: 8390000 | H10: 8490000 | I10: OOS
A11: iPad Pro 11" M2 128GB Wifi | B11: OOS | C11: OOS | D11: 20990000 | E11: N/A | F11: OOS | G11: 19990000 | H11: 20790000 | I11: OOS
A12: iPad Air 5 M1 64GB Wifi | B12: 13949000 | C12: 14090000 | D12: 14090000 | E12: 14290000 | F12: 14790000 | G12: 13990000 | H12: 14290000 | I12: 13903000
A13: iPad Mini 6 64GB Wifi | B13: OOS | C13: 12390000 | D13: 12790000 | E13: 12,190,000 | F13: 12490000 | G13: 11690000 | H13: 12190000 | I13: OOS
A14: iPad Gen 10th 64GB Wifi | B14: 9890000 | C14: 9990000 | D14: 9990000 | E14: 9690000 | F14: 9590000 | G14: 9490000 | H14: 9690000 | I14: 9485000
A15: iPad Gen 9th 64GB Wifi | B15: 7019000 | C15: 7090000 | D15: 7140000 | E15: 6990000 | F15: 6750000 | G15: 6890000 | H15: 6890000 | I15: 6853000
A16: AW SE 2023 (40mm GPS) | B16: 6128000 | C16: 5990000 | D16: 5790000 | E16: 5990000 | F16: 5790000 | G16: 5690000 | H16: 5790000 | I16: 5083000
A17: AW SE 2023 (40mm LTE) | B17: 7415000 | C17: 7490000 | D17: 7290000 | E17: 7490000 | F17: 7190000 | G17: 7190000 | H17: 7390000 | I17: OOS
A18: AW SE 2023 (44mm GPS) | B18: 7019000 | C18: 6890000 | D18: 6790000 | E18: 6790000 | F18: 6690000 | G18: 6590000 | H18: 6590000 | I18: 6665000
A19: AW SE 2023 (44mm LTE) | B19: 8207000 | C19: 7990000 | D19: 7990000 | E19: 8190000 | F19: 8090000 | G19: 7890000 | H19: 7890000 | I19: OOS
A20: AW S9 (41mm GPS) | B20: 9692000 | C20: 9890000 | D20: 9090000 | E20: 9790000 | F20: 8690000 | G20: 8690000 | H20: 8890000 | I20: 8899000
A21: AW S9 (41mm CEL) | B21: 12167000 | C21: 12290000 | D21: 12090000 | E21: 12490000 | F21: 11890000 | G21: 11890000 | H21: 11540000 | I21: OOS
A22: AW S9 (45mm GPS) | B22: 10781000 | C22: 10890000 | D22: 10590000 | E22: 10590000 | F22: 10190000 | G22: 9990000 | H22: 9940000 | I22: OOS
A23: AW S9 (45mm CEL) | B23: 13690000 | C23: 13790000 | D23: 13490000 | E23: 13190000 | F23: 12990000 | G23: 12890000 | H23: 12640000 | I23: OOS
A24: AW Ultra 2 (49mm) | B24: 21090000 | C24: 21190000 | D24: 20990000 | E24: 19990000 | F24: 19990000 | G24: 20890000 | H24: 20890000 | I24: OOS
A25: AirPods Pro 2 - 2023 (C-Type) | B25: 5435000 | C25: 5690000 | D25: 5690000 | E25: 5690000 | F25: 5450000 | G25: 5450000 | H25: 5450000 | I25: OOS
A26: AirPods 3 with charging case | B26: 4090000 | C26: 4090000 | D26: 4090000 | E26: 4090000 | F26: 3850000 | G26: 3790000 | H26: 3950000 | I26: OOS
A27: AirPods 2 with charging case | B27: 2790000 | C27: 2790000 | D27: 2790000 | E27: 2,690,000 | F27: 2690000 | G27: 2590000 | H27: 2690000 | I27: 2623000
A28: MacBook Air 13" M1 8/256Gb | B28: 19097000 | C28: 19290000 | D28: 18990000 | F28: 18690000 | G28: 18190000 | H28: 18190000 | I28: 17851000
A29: MacBook Air 13" M2 8/256GB | B29: 24190000 | C29: 24390000 | D29: 24390000 | F29: 24190000 | G29: 23990000 | H29: 23990000 | I29: 23051000
A30: MacBook Air 13" M3 8/256GB | B30: 27590000 | C30: 27790000 | D30: 27490000 | F30: 26290000 | G30: 26890000 | H30: 26840000 | I30: OOS
A31: MacBook Air 15" M3 8/256GB | B31: 31490000 | C31: 31690000 | D31: 31490000 | F31: 30790000 | G31: 31990000 | H31: 31490000 | I31: OOS
A32: MacBook Pro 14" M3 8/512GB | B32: N/A | C32: 38890000 | D32: 38490000 | F32: 37690000 | G32: 36990000 | H32: 37490000 | I32: OOS

Sheet W9Q1FY26 (2)
B1: TZ | C1: MW | D1: FPT | E1: Viettel | F1: CPS | G1: Shopdunk
A2: iPhone 17 256GB | C2: 24990000 | D2: 24990000 | E2: 24490000 | F2: 24990000 | G2: 24990000
A3: iPhone Air 256G | C3: 30990000 | D3: 30390000 | E3: 29990000 | F3: 30890000 | G3: 30290000 | H3: -400
A4: iPhone 17 Pro 256GB | C4: 34990000 | D4: 34790000 | E4: 33990000 | F4: 33990000 | G4: 34290000 | H4: -200
A5: iPhone 17 Pro Max 256GB | C5: 37990000 | D5: 37990000 | E5: 37490000 | F5: 37990000 | G5: 37490000 | H5: -200
A6: iPhone 16e 128GB | C6: 14990000 | D6: 14990000 | E6: 12490000 | F6: 16990000 | G6: 15190000
A7: iPhone 16 128GB | C7: 21290000 | D7: 20690000 | E7: 20990000 | F7: 20590000 | G7: 20990000
A8: iPhone 16 Plus 128GB | C8: 24990000 | D8: 24690000 | E8: 24190000 | F8: 24590000 | G8: 24490000 | H8: 500
A9: iPhone 16 Pro 128GB | C9: OOS | D9: 25590000 | E9: 24990000 | F9: 25590000 | G9: 24990000
A10: iPhone 16 Pro Max 256GB | C10: 30590000 | D10: 29990000 | E10: 29690000 | F10: 29890000 | G10: 29690000 | H10: -200
A11: iPhone 15 128GB | C11: 17290000 | D11: 16090000 | E11: 16790000 | F11: 16890000 | G11: 16590000
A12: iPhone 15 Plus 128GB | C12: 19590000 | D12: OOS | E12: 18490000 | F12: 17690000 | G12: 18490000
A13: iPhone 14 128GB | C13: 13990000 | D13: 13490000 | E13: 13390000 | F13: 13390000 | G13: 13490000
A14: iPhone 13 128GB | C14: 12390000 | D14: 11990000 | E14: 11990000 | F14: 11990000 | G14: 11890000
A15: iPad Mini 7 128GB Wifi | C15: 11790000 | D15: 11790000 | E15: 11590000 | F15: 11790000 | G15: 11590000
A16: iPad Gen 11th 128GB Wifi | C16: 8490000 | D16: 8490000 | E16: 8390000 | F16: 8690000 | G16: 8390000 | H16: -100 | J16: MW | K16: Duy | L16: TRUE
A17: iPad Air M3 11" 128 GB Wifi | C17: 13190000 | D17: 13190000 | E17: 12790000 | F17: 13390000 | G17: 13190000 | H17: -100 | J17: FPT | K17: Trang | L17: TRUE
A18: iPad Air M3 13" 128 GB Wifi | C18: 18890000 | D18: 18890000 | E18: 20490000 | F18: 18890000 | G18: 18890000 | H18: -100 | J18: Viettel | K18: Nghĩa | L18: TRUE
A19: iPad Pro M4 11" 256 GB Wifi | C19: OOS | D19: 27990000 | E19: OOS | F19: 28190000 | G19: 27990000 | J19: CPS | K19: Hải | L19: TRUE
A20: iPad Pro M4 13" 256 GB Wifi | C20: OOS | D20: 36290000 | E20: 34490000 | F20: 36490000 | G20: 33690000 | J20: ShopDunk | K20: Đạt | L20: TRUE
A21: iPad Pro M5 11” 256GB Wifi | C21: 29990000 | D21: 29990000 | E21: 29490000 | F21: 29990000 | G21: 29590000
A22: iPad Pro M5 13” 256GB Wifi | C22: 39990000 | D22: 39990000 | E22: 39490000 | F22: 39990000 | G22: 39590000
A23: AW SE 3 (40mm GPS) | C23: 6390000 | D23: 6290000 | E23: 6590000 | F23: 5990000 | G23: 6690000
A24: AW SE 3 (40mm LTE) | C24: 8290000 | D24: 8290000 | E24: 7990000 | F24: 8190000 | G24: 8290000 | H24: -200
A25: AW SE 3 (44mm GPS) | C25: 7390000 | D25: 7390000 | E25: 7290000 | F25: 7290000 | G25: 7590000 | H25: -100
A26: AW SE 3 (44mm LTE) | C26: 9090000 | D26: 9350000 | E26: 8790000 | F26: 8990000 | G26: 8990000 | H26: -300
A27: AW S11 (42mm GPS) | C27: 10990000 | D27: 11890000 | E27: 10990000 | F27: 10790000 | G27: 11090000 | H27: -200
A28: AW S11 (42mm CEL) | C28: 14490000 | D28: 14290000 | E28: 13590000 | F28: 14290000 | G28: 14290000 | H28: -100
A29: AW S11 (46mm GPS) | C29: 12090000 | D29: 11790000 | E29: 11490000 | F29: 11790000 | G29: 11990000
A30: AW S11 (46mm CEL) | C30: 15350000 | D30: 15350000 | E30: 14390000 | F30: 15290000 | G30: 15290000
A31: AW Ultra 3 (49mm) | C31: 23990000 | D31: 23990000 | E31: 23490000 | F31: 23990000 | G31: 23990000
A32: AirPods Pro 2 - 2023 (C-Type) | C32: 4790000 | D32: 5290000 | E32: 5590000 | F32: 4790000 | G32: 5590000
A33: AirPods 4 ANC | C33: 4290000 | D33: 4290000 | E33: 4190000 | F33: 4390000 | G33: 4390000
A34: AirPods 4 with charging case | C34: 3090000 | D34: 2990000 | E34: 2890000 | F34: 3090000 | G34: 2890000 | H34: -100
A35: AirPods Pro 3 | C35: 6690000 | D35: 6690000 | E35: 6490000 | F35: 6790000 | G35: 6390000 | H35: -200
A36: MacBook Air 13" M2 16/256GB | C36: 19690000 | D36: 19690000 | F36: 19690000 | G36: 18990000
A37: MacBook Air 13" M4 16/256GB | C37: 25290000 | D37: 24990000 | F37: 24990000 | G37: 24290000
A38: MacBook Air 15" M4 16/256GB | C38: 29590000 | D38: 28990000 | F38: 28990000 | G38: 28290000 | H38: -1400
A39: MacBook Pro 14" M4 16/512GB | C39: OOS | D39: 37990000 | F39: 38590000 | G39: 38990000 | H39: 600
A40: MacBook Pro 14" M5 16/512GB | C40: 41990000 | D40: 41990000 | F40: 41990000 | G40: 41990000
...

Sheet W12Q3FY24
B1: MW | C1: TZ | D1: FPT | E1: Viettel | F1: CPS | G1: Hoang Ha | H1: Shopdunk | I1: Shopee
A2: iPhone 15 128GB | B2: 19590000 | C2: 19590000 | D2: 19490000 | E2: 18490000 | F2: 18890000 | G2: 18690000 | H2: 18740000 | I2: 21610000
A3: iPhone 15 Plus 128GB | B3: 22590000 | C3: 22590000 | D3: 22290000 | E3: 21790000 | F3: 21590000 | G3: 21790000 | H3: 21940000 | I3: 21242000
A4: iPhone 15 Pro 128GB | B4: 25490000 | C4: 25490000 | D4: 25190000 | E4: 23990000 | F4: 24690000 | G4: 24090000 | H4: 24290000 | I4: 23773000
A5: iPhone 15 Pro Max 256GB | B5: 29790000 | C5: 29790000 | D5: 29590000 | E5: 28790000 | F5: 29090000 | G5: 28890000 | H5: 28890000 | I5: 28755000
A6: iPhone 14 Plus 128GB | B6: 19890000 | C6: 19690000 | D6: 19390000 | E6: 19490000 | F6: 19190000 | G6: 18990000 | H6: 18990000 | I6: OOS
A7: iPhone 14 128GB | B7: 17790000 | C7: 17790000 | D7: 17490000 | E7: 16390000 | F7: 16890000 | G7: 16290000 | H7: 16290000 | I7: 23491000
A8: iPhone 13 128GB | B8: 14290000 | C8: 14290000 | D8: 13890000 | E8: 13290000 | F8: 13590000 | G8: 13690000 | H8: 13690000 | I8: 23491000
A9: iPhone 12 64GB | B9: 11990000 | C9: 11990000 | D9: 11890000 | E9: 11490000 | F9: OOS | G9: 11790000 | H9: 12290000 | I9: OOS
A10: iPhone 11 64GB | B10: 8590000 | C10: 8590000 | D10: 8540000 | E10: 8590000 | F10: 8490000 | G10: 8390000 | H10: 8490000 | I10: OOS
A11: iPad Pro 11" M2 128GB Wifi | B11: OOS | C11: OOS | D11: 20990000 | E11: N/A | F11: OOS | G11: 19990000 | H11: 20790000 | I11: OOS
A12: iPad Air 5 M1 64GB Wifi | B12: 14090000 | C12: 14090000 | D12: 13990000 | E12: 14290000 | F12: 14790000 | G12: 13990000 | H12: 14290000 | I12: 15971000
A13: iPad Mini 6 64GB Wifi | B13: OOS | C13: 12390000 | D13: 12690000 | E13: 12,190,000 | F13: 12490000 | G13: 11690000 | H13: 12190000 | I13: 16911000
A14: iPad Gen 10th 64GB Wifi | B14: 10290000 | C14: 10290000 | D14: 9940000 | E14: 9490000 | F14: 9590000 | G14: 9490000 | H14: 9690000 | I14: 10801000
A15: iPad Gen 9th 64GB Wifi | B15: 7190000 | C15: 7190000 | D15: 7040000 | E15: 6790000 | F15: 6750000 | G15: 6890000 | H15: 6890000 | I15: 6853000
A16: AW SE 2023 (40mm GPS) | B16: 6190000 | C16: 5990000 | D16: 5740000 | E16: 5890000 | F16: 5790000 | G16: 5790000 | H16: 5790000 | I16: 5083000
A17: AW SE 2023 (40mm LTE) | B17: 7490000 | C17: 7490000 | D17: 6790000 | E17: 7390000 | F17: 7190000 | G17: 7190000 | H17: 7390000 | I17: OOS
A18: AW SE 2023 (44mm GPS) | B18: 7090000 | C18: 6890000 | D18: 6740000 | E18: 6690000 | F18: 6690000 | G18: 6590000 | H18: 6590000 | I18: 7041000
A19: AW SE 2023 (44mm LTE) | B19: 8290000 | C19: 8290000 | D19: 7540000 | E19: 8090000 | F19: 8090000 | G19: 7890000 | H19: 7890000 | I19: OOS
A20: AW S9 (41mm GPS) | B20: 9790000 | C20: 9890000 | D20: 9390000 | E20: 9690000 | F20: 8690000 | G20: 8690000 | H20: 9040000 | I20: 9467000
A21: AW S9 (41mm CEL) | B21: 12290000 | C21: 12290000 | D21: 11990000 | E21: 12390000 | F21: 11890000 | G21: 11890000 | H21: 11540000 | I21: OOS
A22: AW S9 (45mm GPS) | B22: 10890000 | C22: 10690000 | D22: 10490000 | E22: 10490000 | F22: 9990000 | G22: 9990000 | H22: 9940000 | I22: OOS
A23: AW S9 (45mm CEL) | B23: 13690000 | C23: 13690000 | D23: 13390000 | E23: 13090000 | F23: OOS | G23: 12890000 | H23: 12640000 | I23: OOS
A24: AW Ultra 2 (49mm) | B24: OOS | C24: 21290000 | D24: 20890000 | E24: 19990000 | F24: OOS | G24: 20890000 | H24: 20890000 | I24: OOS
A25: AirPods Pro 2 - 2023 (C-Type) | B25: 5490000 | C25: 5690000 | D25: 5640000 | E25: 5690000 | F25: 5450000 | G25: 5590000 | H25: 5450000 | I25: OOS
A26: AirPods 3 with charging case | B26: 4090000 | C26: 4090000 | D26: 4090000 | E26: 4090000 | F26: 3890000 | G26: 3890000 | H26: 3950000 | I26: OOS
A27: AirPods 2 with charging case | B27: 2790000 | C27: 2790000 | D27: 2790000 | E27: 2,690,000 | F27: 2690000 | G27: 2590000 | H27: 2690000 | I27: 2790000
A28: MacBook Air 13" M1 8/256Gb | B28: 19090000 | C28: 19090000 | D28: 18890000 | F28: 18690000 | G28: 18390000 | H28: 18390000 | I28: 27251000
A29: MacBook Air 13" M2 8/256GB | B29: 24390000 | C29: 24390000 | D29: 24290000 | F29: 24090000 | G29: 23990000 | H29: 23990000 | I29: 23267000
A30: MacBook Air 13" M3 8/256GB | B30: 27690000 | C30: 27690000 | D30: 27390000 | F30: 26490000 | G30: 26890000 | H30: 26840000 | I30: OOS
A31: MacBook Air 15" M3 8/256GB | B31: 31690000 | C31: 31690000 | D31: 31190000 | F31: 31290000 | G31: 31990000 | H31: 31490000 | I31: OOS
A32: MacBook Pro 14" M3 8/512GB | B32: 38690000 | C32: 38690000 | D32: 38190000 | F32: 37590000 | G32: 36990000 | H32: 37490000 | I32: OOS

Sheet W13Q3FY24
B1: MW | C1: TZ | D1: FPT | E1: Viettel | F1: CPS | G1: Hoang Ha | H1: Shopdunk | I1: Shopee
A2: iPhone 15 128GB | B2: 19190000 | C2: 19190000 | D2: 19190000 | E2: 18490000 | F2: 18690000 | G2: 18690000 | H2: 18740000 | I2: 17931000
A3: iPhone 15 Plus 128GB | B3: 22390000 | C3: 22390000 | D3: 22090000 | E3: 21990000 | F3: 21590000 | G3: 21790000 | H3: 21940000 | I3: OOS
A4: iPhone 15 Pro 128GB | B4: 24990000 | C4: 25190000 | D4: 24890000 | E4: 23990000 | F4: 24490000 | G4: 24090000 | H4: 24290000 | I4: 23267000
A5: iPhone 15 Pro Max 256GB | B5: 29390000 | C5: 29390000 | D5: 29290000 | E5: 28990000 | F5: 28890000 | G5: 28790000 | H5: 28890000 | I5: 28143000
A6: iPhone 14 Plus 128GB | B6: 19890000 | C6: 19690000 | D6: 19390000 | E6: 19490000 | F6: 19190000 | G6: 18990000 | H6: 18990000 | I6: 22531000
A7: iPhone 14 128GB | B7: 17790000 | C7: 17790000 | D7: 17490000 | E7: 17590000 | F7: 16990000 | G7: 16290000 | H7: 16290000 | I7: 15723000
A8: iPhone 13 128GB | B8: 13890000 | C8: 13890000 | D8: 13590000 | E8: 13490000 | F8: 13590000 | G8: 13690000 | H8: 13690000 | I8: 12687000
A9: iPhone 12 64GB | B9: 11990000 | C9: 11990000 | D9: 11890000 | E9: 11490000 | F9: OOS | G9: 11790000 | H9: 12290000 | I9: OOS
A10: iPhone 11 64GB | B10: 8590000 | C10: 8590000 | D10: 8540000 | E10: 8590000 | F10: 8490000 | G10: 8390000 | H10: 8490000 | I10: OOS
A11: iPad Pro 11" M2 128GB Wifi | B11: OOS | C11: OOS | D11: 20990000 | E11: N/A | F11: OOS | G11: 19990000 | H11: 20790000 | I11: OOS
A12: iPad Air 5 M1 64GB Wifi | B12: 14090000 | C12: 14090000 | D12: 13990000 | E12: 14290000 | F12: 14590000 | G12: 13990000 | H12: 14290000 | I12: OOS
A13: iPad Mini 6 64GB Wifi | B13: OOS | C13: 12390000 | D13: 12690000 | E13: 12,190,000 | F13: 12490000 | G13: 11690000 | H13: 12190000 | I13: OOS
A14: iPad Gen 10th 64GB Wifi | B14: 10290000 | C14: 10290000 | D14: 9940000 | E14: 9490000 | F14: 9590000 | G14: 9490000 | H14: 9690000 | I14: 9467000
A15: iPad Gen 9th 64GB Wifi | B15: 7090000 | C15: 7090000 | D15: 7140000 | E15: 6790000 | F15: 6790000 | G15: 6850000 | H15: 6890000 | I15: 6707000
A16: AW SE 2023 (40mm GPS) | B16: 6190000 | C16: 5990000 | D16: 5740000 | E16: 5890000 | F16: 5790000 | G16: 5790000 | H16: 5790000 | I16: 5083000
A17: AW SE 2023 (40mm LTE) | B17: 7290000 | C17: 7490000 | D17: 7240000 | E17: 7390000 | F17: 7190000 | G17: 7190000 | H17: 7190000 | I17: OOS
A18: AW SE 2023 (44mm GPS) | B18: 7090000 | C18: 6890000 | D18: 6740000 | E18: 6690000 | F18: 6690000 | G18: 6590000 | H18: 6590000 | I18: 6431000
A19: AW SE 2023 (44mm LTE) | B19: OOS | C19: 7990000 | D19: 7940000 | E19: 8090000 | F19: 8090000 | G19: 7890000 | H19: 7890000 | I19: OOS
A20: AW S9 (41mm GPS) | B20: 9890000 | C20: 9890000 | D20: 9440000 | E20: 9690000 | F20: 8690000 | G20: 8690000 | H20: 9040000 | I20: 8547000
A21: AW S9 (41mm CEL) | B21: 12290000 | C21: 12290000 | D21: 11990000 | E21: 12390000 | F21: 11890000 | G21: 10290000 | H21: 11540000 | I21: OOS
A22: AW S9 (45mm GPS) | B22: 10890000 | C22: 10690000 | D22: 10490000 | E22: 10490000 | F22: 9990000 | G22: 9990000 | H22: 9940000 | I22: OOS
A23: AW S9 (45mm CEL) | B23: 13690000 | C23: 13690000 | D23: 13390000 | E23: 13090000 | F23: OOS | G23: 12890000 | H23: 12640000 | I23: OOS
A24: AW Ultra 2 (49mm) | B24: OOS | C24: 21190000 | D24: 20890000 | E24: 19990000 | F24: OOS | G24: 20890000 | H24: 20890000 | I24: OOS
A25: AirPods Pro 2 - 2023 (C-Type) | B25: 5490000 | C25: 5690000 | D25: 5640000 | E25: 5690000 | F25: 5450000 | G25: 5590000 | H25: 5450000 | I25: 5051000
A26: AirPods 3 with charging case | B26: 4090000 | C26: 4090000 | D26: 4090000 | E26: 4090000 | F26: 3890000 | G26: 3890000 | H26: 3950000 | I26: OOS
A27: AirPods 2 with charging case | B27: 2790000 | C27: 2790000 | D27: 2790000 | E27: 2,690,000 | F27: 2690000 | G27: 2590000 | H27: 2690000 | I27: 2511000
A28: MacBook Air 13" M1 8/256Gb | B28: 19090000 | C28: 19090000 | D28: 18890000 | F28: 18590000 | G28: 18390000 | H28: 18390000 | I28: 26671000
A29: MacBook Air 13" M2 8/256GB | B29: 24390000 | C29: 24390000 | D29: 24290000 | F29: 23990000 | G29: 23990000 | H29: 23990000 | I29: 22990000
A30: MacBook Air 13" M3 8/256GB | B30: 27690000 | C30: 27690000 | D30: 27390000 | F30: 26390000 | G30: 26890000 | H30: 26840000 | I30: 25651000
A31: MacBook Air 15" M3 8/256GB | B31: 31690000 | C31: 31690000 | D31: 31190000 | F31: 31290000 | G31: 31990000 | H31: 31490000 | I31: OOS
A32: MacBook Pro 14" M3 8/512GB | B32: 38690000 | C32: 38690000 | D32: 38190000 | F32: 37590000 | G32: 36990000 | H32: 37490000 | I32: OOS

Sheet W1Q4FY24
B1: MW | C1: TZ | D1: FPT | E1: Viettel | F1: CPS | G1: Hoang Ha | H1: Shopdunk | I1: Shopee
A2: iPhone 15 128GB | B2: 19590000 | C2: 19590000 | D2: 19590000 | E2: 18990000 | F2: 19290000 | G2: 18990000 | H2: 18890000 | I2: 18979000
A3: iPhone 15 Plus 128GB | B3: 22590000 | C3: 22590000 | D3: 22290000 | E3: 21990000 | F3: 22190000 | G3: 21690000 | H3: 22190000 | I3: OOS
A4: iPhone 15 Pro 128GB | B4: 25190000 | C4: 25290000 | D4: 24990000 | E4: 23990000 | F4: 25090000 | G4: 23990000 | H4: 24790000 | I4: 24525000
A5: iPhone 15 Pro Max 256GB | B5: 29490000 | C5: 29490000 | D5: 29290000 | E5: 28890000 | F5: 29190000 | G5: 28690000 | H5: 28990000 | I5: 28943000
A6: iPhone 14 Plus 128GB | B6: 19890000 | C6: 19990000 | D6: 19890000 | E6: 19690000 | F6: 19590000 | G6: 19190000 | H6: 18990000 | I6: 23021000
A7: iPhone 14 128GB | B7: 17790000 | C7: 17790000 | D7: 17490000 | E7: 17690000 | F7: 17290000 | G7: 17190000 | H7: 17290000 | I7: 16406000
A8: iPhone 13 128GB | B8: 14090000 | C8: 14090000 | D8: 13990000 | E8: 13490000 | F8: 13790000 | G8: 13490000 | H8: 13690000 | I8: 13621000
A9: iPhone 12 64GB | B9: 11990000 | C9: 11990000 | D9: 11990000 | E9: 11490000 | F9: 11550000 | G9: 11590000 | H9: 12290000 | I9: OOS
A10: iPhone 11 64GB | B10: 8790000 | C10: 8790000 | D10: 8790000 | E10: 8490000 | F10: 8550000 | G10: 8190000 | H10: 8490000 | I10: OOS
A11: iPad Pro 11" M2 128GB Wifi | B11: OOS | C11: OOS | D11: OOS | E11: N/A | F11: OOS | G11: 19790000 | H11: 20790000 | I11: OOS
A12: iPad Air 5 M1 64GB Wifi | B12: 14090000 | C12: 14090000 | D12: 13990000 | E12: 14170000 | F12: OOS | G12: 13790000 | H12: 14290000 | I12: OOS
A13: iPad Mini 6 64GB Wifi | B13: OOS | C13: 12390000 | D13: 12790000 | E13: 12070000 | F13: 12690000 | G13: 11490000 | H13: 12190000 | I13: OOS
A14: iPad Gen 10th 64GB Wifi | B14: 10290000 | C14: 10290000 | D14: 9990000 | E14: 9593100 | F14: 9690000 | G14: 9290000 | H14: 9690000 | I14: 9485000
A15: iPad Gen 9th 64GB Wifi | B15: 7490000 | C15: 7490000 | D15: 7290000 | E15: 6920100 | F15: 7090000 | G15: 6790000 | H15: 6990000 | I15: 6853000
A16: iPad Air M2 11" 128 GB Wifi | B16: OOS | C16: 16990000 | D16: 16990000 | E16: 16090000 | F16: OOS | G16: 16190000 | H16: 16990000 | I16: OOS
A17: iPad Air M2 13" 128 GB Wifi | B17: 22490000 | C17: 22490000 | D17: 22490000 | E17: 21190000 | F17: 21690000 | G17: 21290000 | H17: 21990000 | I17: 21047000
A18: iPad Pro M4 11" 256 GB Wifi | B18: 28990000 | C18: 28990000 | D18: 28990000 | E18: 27690000 | F18: 37390000 | G18: 27490000 | H18: 28990000 | I18: 27251000
A19: iPad Pro M4 13" 256 GB Wifi | B19: 37990000 | C19: 37990000 | D19: 37990000 | E19: 36490000 | F19: 27990000 | G19: 36190000 | H19: 37990000 | I19: OOS
A20: AW SE 2023 (40mm GPS) | B20: 6190000 | C20: 6190000 | D20: 5690000 | E20: 5930100 | F20: 5890000 | G20: 5590000 | H20: 5890000 | I20: OOS
A21: AW SE 2023 (40mm LTE) | B21: OOS | C21: OOS | D21: OOS | E21: 7217000 | F21: 7290000 | G21: 6990000 | H21: 7390000 | I21: OOS
A22: AW SE 2023 (44mm GPS) | B22: 7090000 | C22: 6890000 | D22: 6290000 | E22: 6623100 | F22: 6990000 | G22: 6390000 | H22: 6790000 | I22: 6665000
A23: AW SE 2023 (44mm LTE) | B23: 8290000 | C23: 8290000 | D23: 7590000 | E23: 8009100 | F23: 8190000 | G23: 7690000 | H23: 7890000 | I23: OOS
A24: AW S9 (41mm GPS) | B24: 9790000 | C24: 9890000 | D24: 9590000 | E24: 9692100 | F24: 9190000 | G24: 8690000 | H24: 9040000 | I24: 9297000
